Workbook

Sheet Top 40
A1: SRET 2027 — Top 40 Students
A2: Ranked by: Test performance 55% · Attendance 30% · Handpicked 15%
A4: Rank | B4: Reg No. | C4: Name | D4: Department | E4: Handpicked | F4: Tests taken /52 | G4: Avg score % | H4: Attendance % | I4: Final score | J4: Watch-outs
A5: 1 | B5: {=INDEX('All Students'!$A$2:$A$124,MATCH($A5,'All Students'!$N$2:$N$124,0))} -> E0223008 | C5: {=INDEX('All Students'!$B$2:$B$124,MATCH($A5,'All Students'!$N$2:$N$124,0))} -> Athena Caleb | D5: {=INDEX('All Students'!$C$2:$C$124,MATCH($A5,'All Students'!$N$2:$N$124,0))} -> B.Tech CSE-CSIOT | E5: {=IF(INDEX('All Students'!$D$2:$D$124,MATCH($A5,'All Students'!$N$2:$N$124,0))=1,INDEX('All Students'!$E$2:$E$124,MATCH($A5,'All Students'!$N$2:$N$124,0)),"No — data pick")} -> CYBER | F5: {=INDEX('All Students'!$F$2:$F$124,MATCH($A5,'All Students'!$N$2:$N$124,0))} -> 48 | G5: {=INDEX('All Students'!$H$2:$H$124,MATCH($A5,'All Students'!$N$2:$N$124,0))} -> 91.5 | H5: {=INDEX('All Students'!$L$2:$L$124,MATCH($A5,'All Students'!$N$2:$N$124,0))} -> 94.5 | I5: {=INDEX('All Students'!$M$2:$M$124,MATCH($A5,'All Students'!$N$2:$N$124,0))} -> 85.095 | J5: {=IF(INDEX('All Students'!$Q$2:$Q$124,MATCH($A5,'All Students'!$N$2:$N$124,0))="","",INDEX('All Students'!$Q$2:$Q$124,MATCH($A5,'All Students'!$N$2:$N$124,0)))}
A6: 2 | B6: {=INDEX('All Students'!$A$2:$A$124,MATCH($A6,'All Students'!$N$2:$N$124,0))} -> E0223003 | C6: {=INDEX('All Students'!$B$2:$B$124,MATCH($A6,'All Students'!$N$2:$N$124,0))} -> Shansita S | D6: {=INDEX('All Students'!$C$2:$C$124,MATCH($A6,'All Students'!$N$2:$N$124,0))} -> B.Tech CSE-CSIOT | E6: {=IF(INDEX('All Students'!$D$2:$D$124,MATCH($A6,'All Students'!$N$2:$N$124,0))=1,INDEX('All Students'!$E$2:$E$124,MATCH($A6,'All Students'!$N$2:$N$124,0)),"No — data pick")} -> CYBER | F6: {=INDEX('All Students'!$F$2:$F$124,MATCH($A6,'All Students'!$N$2:$N$124,0))} -> 44 | G6: {=INDEX('All Students'!$H$2:$H$124,MATCH($A6,'All Students'!$N$2:$N$124,0))} -> 85 | H6: {=INDEX('All Students'!$L$2:$L$124,MATCH($A6,'All Students'!$N$2:$N$124,0))} -> 93.5 | I6: {=INDEX('All Students'!$M$2:$M$124,MATCH($A6,'All Students'!$N$2:$N$124,0))} -> 80.758 | J6: {=IF(INDEX('All Students'!$Q$2:$Q$124,MATCH($A6,'All Students'!$N$2:$N$124,0))="","",INDEX('All Students'!$Q$2:$Q$124,MATCH($A6,'All Students'!$N$2:$N$124,0)))}
A7: 3 | B7: {=INDEX('All Students'!$A$2:$A$124,MATCH($A7,'All Students'!$N$2:$N$124,0))} -> E0323011 | C7: {=INDEX('All Students'!$B$2:$B$124,MATCH($A7,'All Students'!$N$2:$N$124,0))} -> Nithish Kumar | D7: {=INDEX('All Students'!$C$2:$C$124,MATCH($A7,'All Students'!$N$2:$N$124,0))} -> B.Tech CSE-AIDA | E7: {=IF(INDEX('All Students'!$D$2:$D$124,MATCH($A7,'All Students'!$N$2:$N$124,0))=1,INDEX('All Students'!$E$2:$E$124,MATCH($A7,'All Students'!$N$2:$N$124,0)),"No — data pick")} -> AIDA | F7: {=INDEX('All Students'!$F$2:$F$124,MATCH($A7,'All Students'!$N$2:$N$124,0))} -> 45 | G7: {=INDEX('All Students'!$H$2:$H$124,MATCH($A7,'All Students'!$N$2:$N$124,0))} -> 87.4 | H7: {=INDEX('All Students'!$L$2:$L$124,MATCH($A7,'All Students'!$N$2:$N$124,0))} -> 77.9 | I7: {=INDEX('All Students'!$M$2:$M$124,MATCH($A7,'All Students'!$N$2:$N$124,0))} -> 77.772 | J7: {=IF(INDEX('All Students'!$Q$2:$Q$124,MATCH($A7,'All Students'!$N$2:$N$124,0))="","",INDEX('All Students'!$Q$2:$Q$124,MATCH($A7,'All Students'!$N$2:$N$124,0)))}
A8: 4 | B8: {=INDEX('All Students'!$A$2:$A$124,MATCH($A8,'All Students'!$N$2:$N$124,0))} -> E0123034 | C8: {=INDEX('All Students'!$B$2:$B$124,MATCH($A8,'All Students'!$N$2:$N$124,0))} -> Dhanuja Vidya T | D8: {=INDEX('All Students'!$C$2:$C$124,MATCH($A8,'All Students'!$N$2:$N$124,0))} -> B.Tech CSE-AIML | E8: {=IF(INDEX('All Students'!$D$2:$D$124,MATCH($A8,'All Students'!$N$2:$N$124,0))=1,INDEX('All Students'!$E$2:$E$124,MATCH($A8,'All Students'!$N$2:$N$124,0)),"No — data pick")} -> AIML | F8: {=INDEX('All Students'!$F$2:$F$124,MATCH($A8,'All Students'!$N$2:$N$124,0))} -> 34 | G8: {=INDEX('All Students'!$H$2:$H$124,MATCH($A8,'All Students'!$N$2:$N$124,0))} -> 82.5 | H8: {=INDEX('All Students'!$L$2:$L$124,MATCH($A8,'All Students'!$N$2:$N$124,0))} -> 100 | I8: {=INDEX('All Students'!$M$2:$M$124,MATCH($A8,'All Students'!$N$2:$N$124,0))} -> 76.482 | J8: {=IF(INDEX('All Students'!$Q$2:$Q$124,MATCH($A8,'All Students'!$N$2:$N$124,0))="","",INDEX('All Students'!$Q$2:$Q$124,MATCH($A8,'All Students'!$N$2:$N$124,0)))}
A9: 5 | B9: {=INDEX('All Students'!$A$2:$A$124,MATCH($A9,'All Students'!$N$2:$N$124,0))} -> E0423030 | C9: {=INDEX('All Students'!$B$2:$B$124,MATCH($A9,'All Students'!$N$2:$N$124,0))} -> Priyadharshini.H | D9: {=INDEX('All Students'!$C$2:$C$124,MATCH($A9,'All Students'!$N$2:$N$124,0))} -> B.Tech CSME-AIDA | E9: {=IF(INDEX('All Students'!$D$2:$D$124,MATCH($A9,'All Students'!$N$2:$N$124,0))=1,INDEX('All Students'!$E$2:$E$124,MATCH($A9,'All Students'!$N$2:$N$124,0)),"No — data pick")} -> MED | F9: {=INDEX('All Students'!$F$2:$F$124,MATCH($A9,'All Students'!$N$2:$N$124,0))} -> 32 | G9: {=INDEX('All Students'!$H$2:$H$124,MATCH($A9,'All Students'!$N$2:$N$124,0))} -> 75.6 | H9: {=INDEX('All Students'!$L$2:$L$124,MATCH($A9,'All Students'!$N$2:$N$124,0))} -> 100 | I9: {=INDEX('All Students'!$M$2:$M$124,MATCH($A9,'All Students'!$N$2:$N$124,0))} -> 76.174 | J9: {=IF(INDEX('All Students'!$Q$2:$Q$124,MATCH($A9,'All Students'!$N$2:$N$124,0))="","",INDEX('All Students'!$Q$2:$Q$124,MATCH($A9,'All Students'!$N$2:$N$124,0)))}
A10: 6 | B10: {=INDEX('All Students'!$A$2:$A$124,MATCH($A10,'All Students'!$N$2:$N$124,0))} -> E0423002 | C10: {=INDEX('All Students'!$B$2:$B$124,MATCH($A10,'All Students'!$N$2:$N$124,0))} -> Nikhilesh | D10: {=INDEX('All Students'!$C$2:$C$124,MATCH($A10,'All Students'!$N$2:$N$124,0))} -> B.Tech CSME-AIDA | E10: {=IF(INDEX('All Students'!$D$2:$D$124,MATCH($A10,'All Students'!$N$2:$N$124,0))=1,INDEX('All Students'!$E$2:$E$124,MATCH($A10,'All Students'!$N$2:$N$124,0)),"No — data pick")} -> MED | F10: {=INDEX('All Students'!$F$2:$F$124,MATCH($A10,'All Students'!$N$2:$N$124,0))} -> 28 | G10: {=INDEX('All Students'!$H$2:$H$124,MATCH($A10,'All Students'!$N$2:$N$124,0))} -> 92.9 | H10: {=INDEX('All Students'!$L$2:$L$124,MATCH($A10,'All Students'!$N$2:$N$124,0))} -> 86.3 | I10: {=INDEX('All Students'!$M$2:$M$124,MATCH($A10,'All Students'!$N$2:$N$124,0))} -> 75.463 | J10: {=IF(INDEX('All Students'!$Q$2:$Q$124,MATCH($A10,'All Students'!$N$2:$N$124,0))="","",INDEX('All Students'!$Q$2:$Q$124,MATCH($A10,'All Students'!$N$2:$N$124,0)))}
A11: 7 | B11: {=INDEX('All Students'!$A$2:$A$124,MATCH($A11,'All Students'!$N$2:$N$124,0))} -> E0323040 | C11: {=INDEX('All Students'!$B$2:$B$124,MATCH($A11,'All Students'!$N$2:$N$124,0))} -> DARSHAN V | D11: {=INDEX('All Students'!$C$2:$C$124,MATCH($A11,'All Students'!$N$2:$N$124,0))} -> B.Tech CSE-AIDA | E11: {=IF(INDEX('All Students'!$D$2:$D$124,MATCH($A11,'All Students'!$N$2:$N$124,0))=1,INDEX('All Students'!$E$2:$E$124,MATCH($A11,'All Students'!$N$2:$N$124,0)),"No — data pick")} -> AIDA | F11: {=INDEX('All Students'!$F$2:$F$124,MATCH($A11,'All Students'!$N$2:$N$124,0))} -> 42 | G11: {=INDEX('All Students'!$H$2:$H$124,MATCH($A11,'All Students'!$N$2:$N$124,0))} -> 72.5 | H11: {=INDEX('All Students'!$L$2:$L$124,MATCH($A11,'All Students'!$N$2:$N$124,0))} -> 90.9 | I11: {=INDEX('All Students'!$M$2:$M$124,MATCH($A11,'All Students'!$N$2:$N$124,0))} -> 73.169 | J11: {=IF(INDEX('All Students'!$Q$2:$Q$124,MATCH($A11,'All Students'!$N$2:$N$124,0))="","",INDEX('All Students'!$Q$2:$Q$124,MATCH($A11,'All Students'!$N$2:$N$124,0)))} -> Scores in bottom third of test-takers
A12: 8 | B12: {=INDEX('All Students'!$A$2:$A$124,MATCH($A12,'All Students'!$N$2:$N$124,0))} -> E0123021 | C12: {=INDEX('All Students'!$B$2:$B$124,MATCH($A12,'All Students'!$N$2:$N$124,0))} -> Koshree V | D12: {=INDEX('All Students'!$C$2:$C$124,MATCH($A12,'All Students'!$N$2:$N$124,0))} -> B.Tech CSE-AIML | E12: {=IF(INDEX('All Students'!$D$2:$D$124,MATCH($A12,'All Students'!$N$2:$N$124,0))=1,INDEX('All Students'!$E$2:$E$124,MATCH($A12,'All Students'!$N$2:$N$124,0)),"No — data pick")} -> AIML | F12: {=INDEX('All Students'!$F$2:$F$124,MATCH($A12,'All Students'!$N$2:$N$124,0))} -> 29 | G12: {=INDEX('All Students'!$H$2:$H$124,MATCH($A12,'All Students'!$N$2:$N$124,0))} -> 82.2 | H12: {=INDEX('All Students'!$L$2:$L$124,MATCH($A12,'All Students'!$N$2:$N$124,0))} -> 91.8 | I12: {=INDEX('All Students'!$M$2:$M$124,MATCH($A12,'All Students'!$N$2:$N$124,0))} -> 72.559 | J12: {=IF(INDEX('All Students'!$Q$2:$Q$124,MATCH($A12,'All Students'!$N$2:$N$124,0))="","",INDEX('All Students'!$Q$2:$Q$124,MATCH($A12,'All Students'!$N$2:$N$124,0)))}
A13: 9 | B13: {=INDEX('All Students'!$A$2:$A$124,MATCH($A13,'All Students'!$N$2:$N$124,0))} -> E0123049 | C13: {=INDEX('All Students'!$B$2:$B$124,MATCH($A13,'All Students'!$N$2:$N$124,0))} -> Srinath A | D13: {=INDEX('All Students'!$C$2:$C$124,MATCH($A13,'All Students'!$N$2:$N$124,0))} -> B.Tech CSE-AIML | E13: {=IF(INDEX('All Students'!$D$2:$D$124,MATCH($A13,'All Students'!$N$2:$N$124,0))=1,INDEX('All Students'!$E$2:$E$124,MATCH($A13,'All Students'!$N$2:$N$124,0)),"No — data pick")} -> AIML | F13: {=INDEX('All Students'!$F$2:$F$124,MATCH($A13,'All Students'!$N$2:$N$124,0))} -> 26 | G13: {=INDEX('All Students'!$H$2:$H$124,MATCH($A13,'All Students'!$N$2:$N$124,0))} -> 91.2 | H13: {=INDEX('All Students'!$L$2:$L$124,MATCH($A13,'All Students'!$N$2:$N$124,0))} -> 91.8 | I13: {=INDEX('All Students'!$M$2:$M$124,MATCH($A13,'All Students'!$N$2:$N$124,0))} -> 71.822 | J13: {=IF(INDEX('All Students'!$Q$2:$Q$124,MATCH($A13,'All Students'!$N$2:$N$124,0))="","",INDEX('All Students'!$Q$2:$Q$124,MATCH($A13,'All Students'!$N$2:$N$124,0)))}
A14: 10 | B14: {=INDEX('All Students'!$A$2:$A$124,MATCH($A14,'All Students'!$N$2:$N$124,0))} -> E0123015 | C14: {=INDEX('All Students'!$B$2:$B$124,MATCH($A14,'All Students'!$N$2:$N$124,0))} -> Leela Nandha Kishore K S | D14: {=INDEX('All Students'!$C$2:$C$124,MATCH($A14,'All Students'!$N$2:$N$124,0))} -> B.Tech CSE-AIML | E14: {=IF(INDEX('All Students'!$D$2:$D$124,MATCH($A14,'All Students'!$N$2:$N$124,0))=1,INDEX('All Students'!$E$2:$E$124,MATCH($A14,'All Students'!$N$2:$N$124,0)),"No — data pick")} -> AIML | F14: {=INDEX('All Students'!$F$2:$F$124,MATCH($A14,'All Students'!$N$2:$N$124,0))} -> 17 | G14: {=INDEX('All Students'!$H$2:$H$124,MATCH($A14,'All Students'!$N$2:$N$124,0))} -> 96.8 | H14: {=INDEX('All Students'!$L$2:$L$124,MATCH($A14,'All Students'!$N$2:$N$124,0))} -> 85.7 | I14: {=INDEX('All Students'!$M$2:$M$124,MATCH($A14,'All Students'!$N$2:$N$124,0))} -> 71.73 | J14: {=IF(INDEX('All Students'!$Q$2:$Q$124,MATCH($A14,'All Students'!$N$2:$N$124,0))="","",INDEX('All Students'!$Q$2:$Q$124,MATCH($A14,'All Students'!$N$2:$N$124,0)))} -> Only 17/52 tests taken
A15: 11 | B15: {=INDEX('All Students'!$A$2:$A$124,MATCH($A15,'All Students'!$N$2:$N$124,0))} -> E0123007 | C15: {=INDEX('All Students'!$B$2:$B$124,MATCH($A15,'All Students'!$N$2:$N$124,0))} -> GOKUL B | D15: {=INDEX('All Students'!$C$2:$C$124,MATCH($A15,'All Students'!$N$2:$N$124,0))} -> B.Tech CSE-AIML | E15: {=IF(INDEX('All Students'!$D$2:$D$124,MATCH($A15,'All Students'!$N$2:$N$124,0))=1,INDEX('All Students'!$E$2:$E$124,MATCH($A15,'All Students'!$N$2:$N$124,0)),"No — data pick")} -> AIML | F15: {=INDEX('All Students'!$F$2:$F$124,MATCH($A15,'All Students'!$N$2:$N$124,0))} -> 23 | G15: {=INDEX('All Students'!$H$2:$H$124,MATCH($A15,'All Students'!$N$2:$N$124,0))} -> 80.6 | H15: {=INDEX('All Students'!$L$2:$L$124,MATCH($A15,'All Students'!$N$2:$N$124,0))} -> 100 | I15: {=INDEX('All Students'!$M$2:$M$124,MATCH($A15,'All Students'!$N$2:$N$124,0))} -> 71.103 | J15: {=IF(INDEX('All Students'!$Q$2:$Q$124,MATCH($A15,'All Students'!$N$2:$N$124,0))="","",INDEX('All Students'!$Q$2:$Q$124,MATCH($A15,'All Students'!$N$2:$N$124,0)))}
A16: 12 | B16: {=INDEX('All Students'!$A$2:$A$124,MATCH($A16,'All Students'!$N$2:$N$124,0))} -> E0423028 | C16: {=INDEX('All Students'!$B$2:$B$124,MATCH($A16,'All Students'!$N$2:$N$124,0))} -> Prasanna T | D16: {=INDEX('All Students'!$C$2:$C$124,MATCH($A16,'All Students'!$N$2:$N$124,0))} -> B.Tech CSME-AIDA | E16: {=IF(INDEX('All Students'!$D$2:$D$124,MATCH($A16,'All Students'!$N$2:$N$124,0))=1,INDEX('All Students'!$E$2:$E$124,MATCH($A16,'All Students'!$N$2:$N$124,0)),"No — data pick")} -> No — data pick | F16: {=INDEX('All Students'!$F$2:$F$124,MATCH($A16,'All Students'!$N$2:$N$124,0))} -> 41 | G16: {=INDEX('All Students'!$H$2:$H$124,MATCH($A16,'All Students'!$N$2:$N$124,0))} -> 93.2 | H16: {=INDEX('All Students'!$L$2:$L$124,MATCH($A16,'All Students'!$N$2:$N$124,0))} -> 98.6 | I16: {=INDEX('All Students'!$M$2:$M$124,MATCH($A16,'All Students'!$N$2:$N$124,0))} -> 70.742 | J16: {=IF(INDEX('All Students'!$Q$2:$Q$124,MATCH($A16,'All Students'!$N$2:$N$124,0))="","",INDEX('All Students'!$Q$2:$Q$124,MATCH($A16,'All Students'!$N$2:$N$124,0)))} -> Top-15 on data but not handpicked
... A44: 40 | B44: {=INDEX('All Students'!$A$2:$A$124,MATCH($A44,'All Students'!$N$2:$N$124,0))} -> E0423003 | C44: {=INDEX('All Students'!$B$2:$B$124,MATCH($A44,'All Students'!$N$2:$N$124,0))} -> Tarani V | D44: {=INDEX('All Students'!$C$2:$C$124,MATCH($A44,'All Students'!$N$2:$N$124,0))} -> B.Tech CSME-AIDA | E44: {=IF(INDEX('All Students'!$D$2:$D$124,MATCH($A44,'All Students'!$N$2:$N$124,0))=1,INDEX('All Students'!$E$2:$E$124,MATCH($A44,'All Students'!$N$2:$N$124,0)),"No — data pick")} -> MED | F44: {=INDEX('All Students'!$F$2:$F$124,MATCH($A44,'All Students'!$N$2:$N$124,0))} -> 36 | G44: {=INDEX('All Students'!$H$2:$H$124,MATCH($A44,'All Students'!$N$2:$N$124,0))} -> 59.5 | H44: {=INDEX('All Students'!$L$2:$L$124,MATCH($A44,'All Students'!$N$2:$N$124,0))} -> 67.1 | I44: {=INDEX('All Students'!$M$2:$M$124,MATCH($A44,'All Students'!$N$2:$N$124,0))} -> 59.649 | J44: {=IF(INDEX('All Students'!$Q$2:$Q$124,MATCH($A44,'All Students'!$N$2:$N$124,0))="","",INDEX('All Students'!$Q$2:$Q$124,MATCH($A44,'All Students'!$N$2:$N$124,0)))} -> Scores in bottom third of test-takers

Sheet Weights & Method
A1: SRET 2027 — Top 40 Selection Model
A3: Weight | B3: Value
A4: Test performance (PrepInsta) | B4: 0.55
A5: Class attendance | B5: 0.3
A6: Handpicked (classroom attitude) | B6: 0.15
A7: Check: total | B7: {=B4+B5+B6} -> 1
A9: Inside the test score
A10: Skill (avg percentile rank on tests taken) | B10: 0.6
A11: Participation (tests taken) | B11: 0.4
A13: Selection size | B13: 40
A15: How each component is built
A16: Skill | B16: For each of the 52 PrepInsta tests (PI001–PI052), a student's score is converted to a percentile rank among the students who took that test, so hard and easy tests count equally. Averaged over tests taken, then pulled toward 50 by 5 "phantom" tests so a student with 5 lucky attempts does not outrank someone with 45 solid ones.
A17: Participation | B17: 50% share of all 52 tests taken + 50% share of the 35 tests since 31 Aug (PI018 onward), so recent engagement counts more.
A18: Attendance | B18: Duration-weighted attendance % from the Master Attendance Tracker (data as of 29 Aug 2026 — later sessions are not in that file).
A19: Handpicked | B19: 1 if the student is on your classroom-attitude list (35 students), else 0. Worth 15 points out of 100 at the default weight.
A20: Final score | B20: Final = wTest × TestScore + wAttendance × Attendance% + wHandpicked × 100 × Handpicked. Change the blue cells above and every rank and the Top 40 sheet update.
A21: Note | B21: Your list had Advaita as E0223008 and Athena as E0223009; the trackers have them the other way round (E0223008 = Athena Caleb, E0223009 = Advaita Suresh). Both are handpicked, so the result is unaffected. "Priya H" matched E0423030 Priyadharshini.H; "Tarini" = Tarani V; "Hashmitha" = S.H.ASHMITHA.

Sheet All Students
A1: Reg No. | B1: Name | C1: Department | D1: Handpicked (1/0) | E1: Handpicked group | F1: Tests taken /52 | G1: Tests since 31 Aug /35 | H1: Avg score % (tests taken) | I1: Skill (percentile, 0-100) | J1: Participation (0-100) | K1: Test score | L1: Attendance % | M1: Final score | N1: Rank | O1: Top 40? | P1: Data-only rank | Q1: Flags
A2: E0223008 | B2: Athena Caleb | C2: B.Tech CSE-CSIOT | D2: 1 | E2: CYBER | F2: 48 | G2: 33 | H2: 91.5 | I2: 64.3 | J2: 93.3 | K2: {='Weights & Method'!$B$10*I2+'Weights & Method'!$B$11*J2} -> 75.9 | L2: 94.5 | M2: {='Weights & Method'!$B$4*K2+'Weights & Method'!$B$5*L2+'Weights & Method'!$B$6*100*D2} -> 85.095 | N2: {=RANK(M2,$M$2:$M$124)+COUNTIF($M$2:M2,M2)-1} -> 1 | O2: {=IF(N2<='Weights & Method'!$B$13,"Yes","No")} -> Yes | P2: 2
A3: E0223003 | B3: Shansita S | C3: B.Tech CSE-CSIOT | D3: 1 | E3: CYBER | F3: 44 | G3: 28 | H3: 85 | I3: 59.4 | J3: 82.3 | K3: {='Weights & Method'!$B$10*I3+'Weights & Method'!$B$11*J3} -> 68.56 | L3: 93.5 | M3: {='Weights & Method'!$B$4*K3+'Weights & Method'!$B$5*L3+'Weights & Method'!$B$6*100*D3} -> 80.758 | N3: {=RANK(M3,$M$2:$M$124)+COUNTIF($M$2:M3,M3)-1} -> 2 | O3: {=IF(N3<='Weights & Method'!$B$13,"Yes","No")} -> Yes | P3: 5
A4: E0223028 | B4: Neelesh K | C4: B.Tech CSE-CSIOT | D4: 1 | E4: CYBER | F4: 32 | G4: 22 | H4: 81.1 | I4: 51.6 | J4: 62.2 | K4: {='Weights & Method'!$B$10*I4+'Weights & Method'!$B$11*J4} -> 55.84 | L4: 79.5 | M4: {='Weights & Method'!$B$4*K4+'Weights & Method'!$B$5*L4+'Weights & Method'!$B$6*100*D4} -> 69.562 | N4: 15 | O4: {=IF(N4<='Weights & Method'!$B$13,"Yes","No")} -> Yes | P4: 32
A5: E0223002 | B5: Jacelyn Felcita J | C5: B.Tech CSE-CSIOT | D5: 0 | E5: CYBER | F5: 45 | G5: 31 | H5: 90.7 | I5: 69.3 | J5: 87.6 | K5: {='Weights & Method'!$B$10*I5+'Weights & Method'!$B$11*J5} -> 76.62 | L5: 89 | M5: {='Weights & Method'!$B$4*K5+'Weights & Method'!$B$5*L5+'Weights & Method'!$B$6*100*D5} -> 68.841 | N5: 16 | O5: {=IF(N5<='Weights & Method'!$B$13,"Yes","No")} -> Yes | P5: 3 | Q5: Top-15 on data but not handpicked
A6: E0223017 | B6: Arjun V | C6: B.Tech CSE-CSIOT | D6: 1 | E6: CYBER | F6: 18 | G6: 5 | H6: 91 | I6: 69.1 | J6: 24.5 | K6: {='Weights & Method'!$B$10*I6+'Weights & Method'!$B$11*J6} -> 51.26 | L6: 82.6 | M6: {='Weights & Method'!$B$4*K6+'Weights & Method'!$B$5*L6+'Weights & Method'!$B$6*100*D6} -> 67.973 | N6: 17 | O6: {=IF(N6<='Weights & Method'!$B$13,"Yes","No")} -> Yes | P6: 38 | Q6: Only 18/52 tests taken; Mostly inactive on tests since 31 Aug (5/35)
A7: E0223011 | B7: Yuvaraj R | C7: B.Tech CSE-CSIOT | D7: 1 | E7: CYBER | F7: 28 | G7: 14 | H7: 75.9 | I7: 48.5 | J7: 46.9 | K7: {='Weights & Method'!$B$10*I7+'Weights & Method'!$B$11*J7} -> 47.86 | L7: 87.3 | M7: {='Weights & Method'!$B$4*K7+'Weights & Method'!$B$5*L7+'Weights & Method'!$B$6*100*D7} -> 67.513 | N7: 20 | O7: {=IF(N7<='Weights & Method'!$B$13,"Yes","No")} -> Yes | P7: 42
A8: E0223006 | B8: Naveen Sekhar | C8: B.Tech CSE-CSIOT | D8: 1 | E8: CYBER | F8: 17 | G8: 6 | H8: 83.2 | I8: 56.7 | J8: 24.9 | K8: {='Weights & Method'!$B$10*I8+'Weights & Method'!$B$11*J8} -> 43.98 | L8: 93.5 | M8: {='Weights & Method'!$B$4*K8+'Weights & Method'!$B$5*L8+'Weights & Method'!$B$6*100*D8} -> 67.239 | N8: 21 | O8: {=IF(N8<='Weights & Method'!$B$13,"Yes","No")} -> Yes | P8: 43 | Q8: Only 17/52 tests taken; Mostly inactive on tests since 31 Aug (6/35)
A9: E0223014 | B9: Mehul V A | C9: B.Tech CSE-CSIOT | D9: 1 | E9: CYBER | F9: 27 | G9: 14 | H9: 68.5 | I9: 38.3 | J9: 46 | K9: {='Weights & Method'!$B$10*I9+'Weights & Method'!$B$11*J9} -> 41.38 | L9: 94.5 | M9: {='Weights & Method'!$B$4*K9+'Weights & Method'!$B$5*L9+'Weights & Method'!$B$6*100*D9} -> 66.109 | N9: 26 | O9: {=IF(N9<='Weights & Method'!$B$13,"Yes","No")} -> Yes | P9: 52 | Q9: Scores in bottom third of test-takers
A10: E0223009 | B10: Advaita Suresh | C10: B.Tech CSE-CSIOT | D10: 1 | E10: CYBER | F10: 27 | G10: 16 | H10: 55.4 | I10: 30.7 | J10: 48.8 | K10: {='Weights & Method'!$B$10*I10+'Weights & Method'!$B$11*J10} -> 37.94 | L10: 84.1 | M10: {='Weights & Method'!$B$4*K10+'Weights & Method'!$B$5*L10+'Weights & Method'!$B$6*100*D10} -> 61.097 | N10: 37 | O10: {=IF(N10<='Weights & Method'!$B$13,"Yes","No")} -> Yes | P10: 68 | Q10: Scores in bottom third of test-takers
A11: E0223020 | B11: Rujita Balamurugan | C11: B.Tech CSE-CSIOT | D11: 1 | E11: CYBER | F11: 30 | G11: 21 | H11: 78.4 | I11: 47.8 | J11: 58.8 | K11: {='Weights & Method'!$B$10*I11+'Weights & Method'!$B$11*J11} -> 52.2 | L11: 56.2 | M11: {='Weights & Method'!$B$4*K11+'Weights & Method'!$B$5*L11+'Weights & Method'!$B$6*100*D11} -> 60.57 | N11: 38 | O11: {=IF(N11<='Weights & Method'!$B$13,"Yes","No")} -> Yes | P11: 69 | Q11: Class attendance 56%
A12: E0223016 | B12: Kavin Mathi G R | C12: B.Tech CSE-CSIOT | D12: 0 | E12: CYBER | F12: 42 | G12: 27 | H12: 65.9 | I12: 38.4 | J12: 79 | K12: {='Weights & Method'!$B$10*I12+'Weights & Method'!$B$11*J12} -> 54.64 | L12: 98.6 | M12: {='Weights & Method'!$B$4*K12+'Weights & Method'!$B$5*L12+'Weights & Method'!$B$6*100*D12} -> 59.632 | N12: 41 | O12: {=IF(N12<='Weights & Method'!$B$13,"Yes","No")} -> No | P12: 16 | Q12: Scores in bottom third of test-takers
A13: E0223023 | B13: Sethukannan M | C13: B.Tech CSE-CSIOT | D13: 0 | E13: CYBER | F13: 30 | G13: 17 | H13: 82.9 | I13: 57.5 | J13: 53.1 | K13: {='Weights & Method'!$B$10*I13+'Weights & Method'!$B$11*J13} -> 55.74 | L13: 83.3 | M13: {='Weights & Method'!$B$4*K13+'Weights & Method'!$B$5*L13+'Weights & Method'!$B$6*100*D13} -> 55.647 | N13: 50 | O13: {=IF(N13<='Weights & Method'!$B$13,"Yes","No")} -> No | P13: 28
A14: E0223027 | B14: S S Yogalakshmi | C14: B.Tech CSE-CSIOT | D14: 0 | E14: CYBER | F14: 34 | G14: 19 | H14: 77.7 | I14: 51.1 | J14: 59.8 | K14: {='Weights & Method'!$B$10*I14+'Weights & Method'!$B$11*J14} -> 54.58 | L14: 84.8 | M14: {='Weights & Method'!$B$4*K14+'Weights & Method'!$B$5*L14+'Weights & Method'!$B$6*100*D14} -> 55.459 | N14: 51 | O14: {=IF(N14<='Weights & Method'!$B$13,"Yes","No")} -> No | P14: 29
A15: E0223013 | B15: Harini S | C15: B.Tech CSE-CSIOT | D15: 0 | E15: CYBER | F15: 34 | G15: 21 | H15: 61.3 | I15: 30.5 | J15: 62.7 | K15: {='Weights & Method'!$B$10*I15+'Weights & Method'!$B$11*J15} -> 43.38 | L15: 84.9 | M15: {='Weights & Method'!$B$4*K15+'Weights & Method'!$B$5*L15+'Weights & Method'!$B$6*100*D15} -> 49.329 | N15: 65 | O15: {=IF(N15<='Weights & Method'!$B$13,"Yes","No")} -> No | P15: 54 | Q15: Scores in bottom third of test-takers
A16: E0223007 | B16: Midhun K | C16: B.Tech CSE-CSIOT | D16: 0 | E16: CYBER | F16: 10 | G16: 3 | H16: 79.5 | I16: 53.7 | J16: 13.9 | K16: {='Weights & Method'!$B$10*I16+'Weights & Method'!$B$11*J16} -> 37.78 | L16: 89 | M16: {='Weights & Method'!$B$4*K16+'Weights & Method'!$B$5*L16+'Weights & Method'!$B$6*100*D16} -> 47.479 | N16: 75 | O16: {=IF(N16<='Weights & Method'!$B$13,"Yes","No")} -> No | P16: 65 | Q16: Only 10/52 tests taken; Mostly inactive on tests since 31 Aug (3/35)
A17: E0223024 | B17: Balaji S | C17: B.Tech CSE-CSIOT | D17: 0 | E17: CYBER | F17: 14 | G17: 5 | H17: 47.5 | I17: 27.2 | J17: 20.6 | K17: {='Weights & Method'!$B$10*I17+'Weights & Method'!$B$11*J17} -> 24.56 | L17: 100 | M17: {='Weights & Method'!$B$4*K17+'Weights & Method'!$B$5*L17+'Weights & Method'!$B$6*100*D17} -> 43.508 | N17: 79 | O17: {=IF(N17<='Weights & Method'!$B$13,"Yes","No")} -> No | P17: 75 | Q17: Only 14/52 tests taken; Mostly inactive on tests since 31 Aug (5/35); Scores in bottom third of test-takers
A18: E0223001 | B18: Vignesh R | C18: B.Tech CSE-CSIOT | D18: 0 | E18: CYBER | F18: 2 | G18: 0 | H18: 52.4 | I18: 43.3 | J18: 1.9 | K18: {='Weights & Method'!$B$10*I18+'Weights & Method'!$B$11*J18} -> 26.74 | L18: 93.2 | M18: {='Weights & Method'!$B$4*K18+'Weights & Method'!$B$5*L18+'Weights & Method'!$B$6*100*D18} -> 42.667 | N18: 82 | O18: {=IF(N18<='Weights & Method'!$B$13,"Yes","No")} -> No | P18: 78 | Q18: Only 2/52 tests taken; Mostly inactive on tests since 31 Aug (0/35)
A19: E0223030 | B19: Dharani S | C19: B.Tech CSE-CSIOT | D19: 0 | E19: CYBER | F19: 10 | G19: 7 | H19: 91.7 | I19: 51.7 | J19: 19.6 | K19: {='Weights & Method'!$B$10*I19+'Weights & Method'!$B$11*J19} -> 38.86 | L19: 67.6 | M19: {='Weights & Method'!$B$4*K19+'Weights & Method'!$B$5*L19+'Weights & Method'!$B$6*100*D19} -> 41.653 | N19: 85 | O19: {=IF(N19<='Weights & Method'!$B$13,"Yes","No")} -> No | P19: 83 | Q19: Only 10/52 tests taken
A20: E0223015 | B20: Vimalraj P | C20: B.Tech CSE-CSIOT | D20: 0 | E20: CYBER | F20: 11 | G20: 6 | H20: 10.2 | I20: 19 | J20: 19.1 | K20: {='Weights & Method'!$B$10*I20+'Weights & Method'!$B$11*J20} -> 19.04 | L20: 100 | M20: {='Weights & Method'!$B$4*K20+'Weights & Method'!$B$5*L20+'Weights & Method'!$B$6*100*D20} -> 40.472 | N20: 89 | O20: {=IF(N20<='Weights & Method'!$B$13,"Yes","No")} -> No | P20: 89 | Q20: Only 11/52 tests taken; Mostly inactive on tests since 31 Aug (6/35); Scores in bottom third of test-takers
A21: E0223022 | B21: Navadeep K M | C21: B.Tech CSE-CSIOT | D21: 0 | E21: CYBER | F21: 8 | G21: 2 | H21: 66.5 | I21: 44.3 | J21: 10.5 | K21: {='Weights & Method'!$B$10*I21+'Weights & Method'!$B$11*J21} -> 30.78 | L21: 51.5 | M21: {='Weights & Method'!$B$4*K21+'Weights & Method'!$B$5*L21+'Weights & Method'!$B$6*100*D21} -> 32.379 | N21: 104 | O21: {=IF(N21<='Weights & Method'!$B$13,"Yes","No")} -> No | P21: 104 | Q21: Only 8/52 tests taken; Mostly inactive on tests since 31 Aug (2/35); Class attendance 52%
A22: E0223019 | B22: Mohammed Nasrullah M | C22: B.Tech CSE-CSIOT | D22: 0 | E22: CYBER | F22: 0 | G22: 0 | I22: 0 | J22: 0 | K22: {='Weights & Method'!$B$10*I22+'Weights & Method'!$B$11*J22} -> 0 | L22: 82.2 | M22: {='Weights & Method'!$B$4*K22+'Weights & Method'!$B$5*L22+'Weights & Method'!$B$6*100*D22} -> 24.66 | N22: 112 | O22: {=IF(N22<='Weights & Method'!$B$13,"Yes","No")} -> No | P22: 112 | Q22: Only 0/52 tests taken; Mostly inactive on tests since 31 Aug (0/35)
A23: E0223029 | B23: Vishal | C23: B.Tech CSE-CSIOT | D23: 0 | E23: CYBER | F23: 0 | G23: 0 | I23: 0 | J23: 0 | K23: {='Weights & Method'!$B$10*I23+'Weights & Method'!$B$11*J23} -> 0 | L23: 0 | M23: {='Weights & Method'!$B$4*K23+'Weights & Method'!$B$5*L23+'Weights & Method'!$B$6*100*D23} -> 0 | N23: {=RANK(M23,$M$2:$M$124)+COUNTIF($M$2:M124,M23)-1} -> 123 | O23: {=IF(N23<='Weights & Method'!$B$13,"Yes","No")} -> No | P23: 123 | Q23: Only 0/52 tests taken; Mostly inactive on tests since 31 Aug (0/35); Class attendance 0%
A24: E0323011 | B24: Nithish Kumar | C24: B.Tech CSE-AIDA | D24: 1 | E24: AIDA | F24: 45 | G24: 31 | H24: 87.4 | I24: 61 | J24: 87.6 | K24: {='Weights & Method'!$B$10*I24+'Weights & Method'!$B$11*J24} -> 71.64 | L24: 77.9 | M24: {='Weights & Method'!$B$4*K24+'Weights & Method'!$B$5*L24+'Weights & Method'!$B$6*100*D24} -> 77.772 | N24: 3 | O24: {=IF(N24<='Weights & Method'!$B$13,"Yes","No")} -> Yes | P24: 9
A25: E0323040 | B25: DARSHAN V | C25: B.Tech CSE-AIDA | D25: 1 | E25: AIDA | F25: 42 | G25: 29 | H25: 72.5 | I25: 39.1 | J25: 81.8 | K25: {='Weights & Method'!$B$10*I25+'Weights & Method'!$B$11*J25} -> 56.18 | L25: 90.9 | M25: {='Weights & Method'!$B$4*K25+'Weights & Method'!$B$5*L25+'Weights & Method'!$B$6*100*D25} -> 73.169 | N25: 7 | O25: {=IF(N25<='Weights & Method'!$B$13,"Yes","No")} -> Yes | P25: 20 | Q25: Scores in bottom third of test-takers
A26: E0323029 | B26: Ganesh K | C26: B.Tech CSE-AIDA | D26: 1 | E26: AIDA | F26: 33 | G26: 21 | H26: 72.2 | I26: 49 | J26: 61.7 | K26: {='Weights & Method'!$B$10*I26+'Weights & Method'!$B$11*J26} -> 54.08 | L26: 85.7 | M26: {='Weights & Method'!$B$4*K26+'Weights & Method'!$B$5*L26+'Weights & Method'!$B$6*100*D26} -> 70.454 | N26: 13 | O26: {=IF(N26<='Weights & Method'!$B$13,"Yes","No")} -> Yes | P26: 30
A27: E0323048 | B27: Tejaswini.R.J | C27: B.Tech CSE-AIDA | D27: 1 | E27: AIDA | F27: 28 | G27: 17 | H27: 74.7 | I27: 46.1 | J27: 51.2 | K27: {='Weights & Method'!$B$10*I27+'Weights & Method'!$B$11*J27} -> 48.14 | L27: 94.8 | M27: {='Weights & Method'!$B$4*K27+'Weights & Method'!$B$5*L27+'Weights & Method'!$B$6*100*D27} -> 69.917 | N27: 14 | O27: {=IF(N27<='Weights & Method'!$B$13,"Yes","No")} -> Yes | P27: 31
A28: E0323009 | B28: Varnika Ramesh | C28: B.Tech CSE-AIDA | D28: 1 | E28: AIDA | F28: 20 | G28: 7 | H28: 79.1 | I28: 58.8 | J28: 29.2 | K28: {='Weights & Method'!$B$10*I28+'Weights & Method'!$B$11*J28} -> 46.96 | L28: 89.6 | M28: {='Weights & Method'!$B$4*K28+'Weights & Method'!$B$5*L28+'Weights & Method'!$B$6*100*D28} -> 67.708 | N28: 18 | O28: {=IF(N28<='Weights & Method'!$B$13,"Yes","No")} -> Yes | P28: 40
A29: E0323014 | B29: Sharmila S | C29: B.Tech CSE-AIDA | D29: 1 | E29: AIDA | F29: 32 | G29: 28 | H29: 81.4 | I29: 57.7 | J29: 70.8 | K29: {='Weights & Method'!$B$10*I29+'Weights & Method'!$B$11*J29} -> 62.94 | L29: 60.3 | M29: {='Weights & Method'!$B$4*K29+'Weights & Method'!$B$5*L29+'Weights & Method'!$B$6*100*D29} -> 67.707 | N29: 19 | O29: {=IF(N29<='Weights & Method'!$B$13,"Yes","No")} -> Yes | P29: 39 | Q29: Class attendance 60%
A30: E0323019 | B30: SEJONE THOMAS FRANK | C30: B.Tech CSE-AIDA | D30: 0 | E30: AIDA | F30: 35 | G30: 21 | H30: 88.2 | I30: 60.4 | J30: 63.7 | K30: {='Weights & Method'!$B$10*I30+'Weights & Method'!$B$11*J30} -> 61.72 | L30: 92.2 | M30: {='Weights & Method'!$B$4*K30+'Weights & Method'!$B$5*L30+'Weights & Method'!$B$6*100*D30} -> 61.606 | N30: 35 | O30: {=IF(N30<='Weights & Method'!$B$13,"Yes","No")} -> Yes | P30: 12 | Q30: Top-15 on data but not handpicked
A31: E0323043 | B31: VEDHASRI K | C31: B.Tech CSE-AIDA | D31: 0 | E31: AIDA | F31: 36 | G31: 25 | H31: 70.2 | I31: 44 | J31: 70.3 | K31: {='Weights & Method'!$B$10*I31+'Weights & Method'!$B$11*J31} -> 54.52 | L31: 94.8 | M31: {='Weights & Method'!$B$4*K31+'Weights & Method'!$B$5*L31+'Weights & Method'!$B$6*100*D31} -> 58.426 | N31: 44 | O31: {=IF(N31<='Weights & Method'!$B$13,"Yes","No")} -> No | P31: 19
A32: E0323026 | B32: Madhu shree.D | C32: B.Tech CSE-AIDA | D32: 0 | E32: AIDA | F32: 31 | G32: 18 | H32: 78.4 | I32: 48.4 | J32: 55.5 | K32: {='Weights & Method'!$B$10*I32+'Weights & Method'!$B$11*J32} -> 51.24 | L32: 98.7 | M32: {='Weights & Method'!$B$4*K32+'Weights & Method'!$B$5*L32+'Weights & Method'!$B$6*100*D32} -> 57.792 | N32: 46 | O32: {=IF(N32<='Weights & Method'!$B$13,"Yes","No")} -> No | P32: 22
A33: E0323015 | B33: Yokesh kannan R | C33: B.Tech CSE-AIDA | D33: 0 | E33: AIDA | F33: 22 | G33: 12 | H33: 69.7 | I33: 45.3 | J33: 38.3 | K33: {='Weights & Method'!$B$10*I33+'Weights & Method'!$B$11*J33} -> 42.5 | L33: 100 | M33: {='Weights & Method'!$B$4*K33+'Weights & Method'!$B$5*L33+'Weights & Method'!$B$6*100*D33} -> 53.375 | N33: 54 | O33: {=IF(N33<='Weights & Method'!$B$13,"Yes","No")} -> No | P33: 36
A34: E0323045 | B34: T.kumaraguru | C34: B.Tech CSE-AIDA | D34: 0 | E34: AIDA | F34: 35 | G34: 22 | H34: 70.3 | I34: 41 | J34: 65.1 | K34: {='Weights & Method'!$B$10*I34+'Weights & Method'!$B$11*J34} -> 50.64 | L34: 84.4 | M34: {='Weights & Method'!$B$4*K34+'Weights & Method'!$B$5*L34+'Weights & Method'!$B$6*100*D34} -> 53.172 | N34: 56 | O34: {=IF(N34<='Weights & Method'!$B$13,"Yes","No")} -> No | P34: 37
A35: E0323012 | B35: Anu D | C35: B.Tech CSE-AIDA | D35: 0 | E35: AIDA | F35: 20 | G35: 7 | H35: 71.8 | I35: 51 | J35: 29.2 | K35: {='Weights & Method'!$B$10*I35+'Weights & Method'!$B$11*J35} -> 42.28 | L35: 96.1 | M35: {='Weights & Method'!$B$4*K35+'Weights & Method'!$B$5*L35+'Weights & Method'!$B$6*100*D35} -> 52.084 | N35: 58 | O35: {=IF(N35<='Weights & Method'!$B$13,"Yes","No")} -> No | P35: 44
A36: E0323022 | B36: S.Lokesh krishna | C36: B.Tech CSE-AIDA | D36: 0 | E36: AIDA | F36: 28 | G36: 17 | H36: 82 | I36: 53.8 | J36: 51.2 | K36: {='Weights & Method'!$B$10*I36+'Weights & Method'!$B$11*J36} -> 52.76 | L36: 68.8 | M36: {='Weights & Method'!$B$4*K36+'Weights & Method'!$B$5*L36+'Weights & Method'!$B$6*100*D36} -> 49.658 | N36: 64 | O36: {=IF(N36<='Weights & Method'!$B$13,"Yes","No")} -> No | P36: 53
A37: E0323024 | B37: Jaswant raj GV | C37: B.Tech CSE-AIDA | D37: 0 | E37: AIDA | F37: 25 | G37: 14 | H37: 75.1 | I37: 46.9 | J37: 44 | K37: {='Weights & Method'!$B$10*I37+'Weights & Method'!$B$11*J37} -> 45.74 | L37: 79.5 | M37: {='Weights & Method'!$B$4*K37+'Weights & Method'!$B$5*L37+'Weights & Method'!$B$6*100*D37} -> 49.007 | N37: 66 | O37: {=IF(N37<='Weights & Method'!$B$13,"Yes","No")} -> No | P37: 55
A38: E0323042 | B38: Dejhovathiyan S | C38: B.Tech CSE-AIDA | D38: 0 | E38: AIDA | F38: 33 | G38: 22 | H38: 45.9 | I38: 23.4 | J38: 63.2 | K38: {='Weights & Method'!$B$10*I38+'Weights & Method'!$B$11*J38} -> 39.32 | L38: 89.6 | M38: {='Weights & Method'!$B$4*K38+'Weights & Method'!$B$5*L38+'Weights & Method'!$B$6*100*D38} -> 48.506 | N38: 70 | O38: {=IF(N38<='Weights & Method'!$B$13,"Yes","No")} -> No | P38: 62 | Q38: Scores in bottom third of test-takers
A39: E0323039 | B39: Divakar V | C39: B.Tech CSE-AIDA | D39: 0 | E39: AIDA | F39: 13 | G39: 4 | H39: 79.1 | I39: 60.4 | J39: 18.2 | K39: {='Weights & Method'!$B$10*I39+'Weights & Method'!$B$11*J39} -> 43.52 | L39: 81.8 | M39: {='Weights & Method'!$B$4*K39+'Weights & Method'!$B$5*L39+'Weights & Method'!$B$6*100*D39} -> 48.476 | N39: 71 | O39: {=IF(N39<='Weights & Method'!$B$13,"Yes","No")} -> No | P39: 61 | Q39: Only 13/52 tests taken; Mostly inactive on tests since 31 Aug (4/35)
A40: E0323030 | B40: Ajith Jayya Surya.E | C40: B.Tech CSE-AIDA | D40: 0 | E40: AIDA | F40: 16 | G40: 3 | H40: 84.7 | I40: 59.7 | J40: 19.7 | K40: {='Weights & Method'!$B$10*I40+'Weights & Method'!$B$11*J40} -> 43.7 | L40: 80.5 | M40: {='Weights & Method'!$B$4*K40+'Weights & Method'!$B$5*L40+'Weights & Method'!$B$6*100*D40} -> 48.185 | N40: 73 | O40: {=IF(N40<='Weights & Method'!$B$13,"Yes","No")} -> No | P40: 64 | Q40: Only 16/52 tests taken; Mostly inactive on tests since 31 Aug (3/35)
...
